{"trial_id": "0", "hyperparameters": {"space": [{"class_name": "Int", "config": {"name": "units", "default": null, "conditions": [], "min_value": 8, "max_value": 128, "step": 8, "sampling": "linear"}}], "values": {"units": 8}}, "metrics": {"metrics": {}}, "score": null, "best_step": 0, "status": "FAILED", "message": "Traceback (most recent call last):\n  File \"E:\\anaconda\\envs\\tf\\lib\\site-packages\\keras_tuner\\engine\\base_tuner.py\", line 270, in _try_run_and_update_trial\n    self._run_and_update_trial(trial, *fit_args, **fit_kwargs)\n  File \"E:\\anaconda\\envs\\tf\\lib\\site-packages\\keras_tuner\\engine\\base_tuner.py\", line 235, in _run_and_update_trial\n    results = self.run_trial(trial, *fit_args, **fit_kwargs)\n  File \"E:\\anaconda\\envs\\tf\\lib\\site-packages\\keras_tuner\\engine\\tuner.py\", line 287, in run_trial\n    obj_value = self._build_and_fit_model(trial, *args, **copied_kwargs)\n  File \"E:\\anaconda\\envs\\tf\\lib\\site-packages\\keras_tuner\\engine\\tuner.py\", line 214, in _build_and_fit_model\n    results = self.hypermodel.fit(hp, model, *args, **kwargs)\n  File \"E:\\anaconda\\envs\\tf\\lib\\site-packages\\keras_tuner\\engine\\hypermodel.py\", line 144, in fit\n    return model.fit(*args, **kwargs)\n  File \"E:\\anaconda\\envs\\tf\\lib\\site-packages\\keras\\utils\\traceback_utils.py\", line 70, in error_handler\n    raise e.with_traceback(filtered_tb) from None\n  File \"C:\\Users\\Mrunmay\\AppData\\Local\\Temp\\__autograph_generated_fileanl9fcww.py\", line 15, in tf__train_function\n    retval_ = ag__.converted_call(ag__.ld(step_function), (ag__.ld(self), ag__.ld(iterator)), None, fscope)\nValueError: in user code:\n\n    File \"E:\\anaconda\\envs\\tf\\lib\\site-packages\\keras\\engine\\training.py\", line 1160, in train_function  *\n        return step_function(self, iterator)\n    File \"E:\\anaconda\\envs\\tf\\lib\\site-packages\\keras\\engine\\training.py\", line 1146, in step_function  **\n        outputs = model.distribute_strategy.run(run_step, args=(data,))\n    File \"E:\\anaconda\\envs\\tf\\lib\\site-packages\\keras\\engine\\training.py\", line 1135, in run_step  **\n        outputs = model.train_step(data)\n    File \"E:\\anaconda\\envs\\tf\\lib\\site-packages\\keras\\engine\\training.py\", line 994, in train_step\n        loss = self.compute_loss(x, y, y_pred, sample_weight)\n    File \"E:\\anaconda\\envs\\tf\\lib\\site-packages\\keras\\engine\\training.py\", line 1052, in compute_loss\n        return self.compiled_loss(\n    File \"E:\\anaconda\\envs\\tf\\lib\\site-packages\\keras\\engine\\compile_utils.py\", line 265, in __call__\n        loss_value = loss_obj(y_t, y_p, sample_weight=sw)\n    File \"E:\\anaconda\\envs\\tf\\lib\\site-packages\\keras\\losses.py\", line 152, in __call__\n        losses = call_fn(y_true, y_pred)\n    File \"E:\\anaconda\\envs\\tf\\lib\\site-packages\\keras\\losses.py\", line 272, in call  **\n        return ag_fn(y_true, y_pred, **self._fn_kwargs)\n    File \"E:\\anaconda\\envs\\tf\\lib\\site-packages\\keras\\losses.py\", line 2162, in binary_crossentropy\n        backend.binary_crossentropy(y_true, y_pred, from_logits=from_logits),\n    File \"E:\\anaconda\\envs\\tf\\lib\\site-packages\\keras\\backend.py\", line 5677, in binary_crossentropy\n        return tf.nn.sigmoid_cross_entropy_with_logits(\n\n    ValueError: `logits` and `labels` must have the same shape, received ((None, 8) vs (None, 1)).\n\n"}